Workbook

Sheet 报价说明
A1: ENGCHAIN 工程链 3.0 平台开发报价表 · 填报说明
A3: 一、项目基本信息
A4: 项目名称 | B4: ENGCHAIN 工程链 3.0 平台开发（用户端 Web + 管理后台 + 4 小程序 + 3 App）
A5: 招标方式 | B5: 邀请比价（邀标）
A6: 项目预算 | B6: 人民币 15 万元（含税总价上限）
A7: 项目工期 | B7: 3 个月（自合同签订之日起）
A9: 二、报价口径
A10: 1. 含税报价 | B10: 报价表内全部金额均为含税人民币报价（默认增值税专用发票，税率如有不同请在备注说明）。
A11: 2. 填报方式 | B11: 请在「报价表」工作表中填写黄色单元格（报价人天、人天单价、备注）；小计与合计由公式自动计算，请勿修改公式。
A12: 3. 分模块报价 | B12: 各功能模块按工作项独立报价，报价应覆盖需求书所列全部需求要点（含后端、数据库、多端适配与第三方联调）。
A13: 4. 实施周期 | B13: 请在报价汇总中承诺总实施周期（天），并建议给出 M1/M2/M3 各阶段完成时间。
A14: 5. 免费维护期 | B14: 请承诺验收通过后的免费维护期（建议不少于 1 个月），超出部分另行报价。
A15: 6. 增项计价 | B15: 超出本需求书范围的增项需求，按填报的人天单价另行计价。
A16: 7. 付款节点 | B16: 建议：签约 30%、M1 验收 30%、M2 验收 20%、上线验收 20%；以商务合同为准。
A18: 三、投标材料 | B18: 报价表（本表）、营业执照、同类项目案例 1-2 个（附截图或链接）、团队配置与排期承诺。
A20: 四、联系方式 | B20: 联系人：【待填写】；电话/邮箱：【待填写】；回标截止：【待填写】。

Sheet 报价表
A1: ENGCHAIN 工程链 3.0 平台开发报价表（黄色单元格由乙方填写）
A2: 编号 | B2: 报价项 | C2: 需求说明 | D2: 报价人天 | E2: 人天单价（元） | F2: 小计（元） | G2: 备注
A3: A1 | B3: 账号体系与认证 | C3: 注册/登录（短信验证码）、多级实名认证（个人/企业工商/合伙人/资质）、认证审核联动、封禁与资金冻结 | F3: =IF(OR(D3="",E3=""),"",D3*E3)
A4: A2 | B4: 消息与沟通 | C4: 消息列表、双人聊天 IM、系统消息、订阅通知与消息推送 | F4: =IF(OR(D4="",E4=""),"",D4*E4)
A5: A3 | B5: 搜索与匹配 | C5: 全文搜索、筛选排序、匹配度排序、匹配偏好设置 | F5: =IF(OR(D5="",E5=""),"",D5*E5)
A6: A4 | B6: 管理后台框架与权限 | C6: 后台基础框架、RBAC 角色权限、操作日志 | F6: =IF(OR(D6="",E6=""),"",D6*E6)
A7: A5 | B7: 数据迁移 | C7: 现有原型示例数据迁移至正式数据库 | F7: =IF(OR(D7="",E7=""),"",D7*E7)
A8: A 平台基础 小计 | D8: =SUM(D3:D7) | E8: =ROUND(SUM(F3:F7)/IF(SUM(D3:D7)=0,1,SUM(D3:D7)),0) | F8: =SUM(F3:F7)
A9: B1 | B9: 信息发布与供需 | C9: 9 类信息编辑器、草稿箱、发布审核与上下架、我的发布 | F9: =IF(OR(D9="",E9=""),"",D9*E9)
A10: B2 | B10: 线索解锁与免费额度 | C10: 积分/余额付费解锁联系方式、免费额度控制、解锁记录 | F10: =IF(OR(D10="",E10=""),"",D10*E10)
A11: B3 | B11: 订单系统 | C11: 普通订单与中介托管订单、状态机流转（待支付/进行中/待验收/已完成/已退款） | F11: =IF(OR(D11="",E11=""),"",D11*E11)
A12: B4 | B12: 资金托管 | C12: 建设银行托管对接（冻结/验收打款/14 天自动确认/异议仲裁）、托管资金台账 | F12: =IF(OR(D12="",E12=""),"",D12*E12)
A13: B5 | B13: 退款与申诉 | C13: 7 天无理由退款、申诉与平台仲裁流程 | F13: =IF(OR(D13="",E13=""),"",D13*E13)
A14: B 核心交易 小计 | D14: =SUM(D9:D13) | E14: =ROUND(SUM(F9:F13)/IF(SUM(D9:D13)=0,1,SUM(D9:D13)),0) | F14: =SUM(F9:F13)
A15: C1 | B15: 钱包账户 | C15: 余额账户（可用/在途/冻结）、收支明细流水 | F15: =IF(OR(D15="",E15=""),"",D15*E15)
A16: C2 | B16: 充值 | C16: 微信支付、支付宝、对公转账确认（后台审批） | F16: =IF(OR(D16="",E16=""),"",D16*E16)
A17: C3 | B17: 提现 | C17: 提现两级审批、T+0/T+1 到账、银行卡管理 | F17: =IF(OR(D17="",E17=""),"",D17*E17)
A18: C4 | B18: 积分体系 | C18: 积分获取/消耗规则、积分抵现、积分商城 | F18: =IF(OR(D18="",E18=""),"",D18*E18)
A19: C5 | B19: 发票管理 | C19: 抬头管理、开票信息维护、开票申请与记录 | F19: =IF(OR(D19="",E19=""),"",D19*E19)
A20: C6 | B20: 年度会员与免费额度 | C20: 会员权益、免费额度规则与配置 | F20: =IF(OR(D20="",E20=""),"",D20*E20)
A21: C 资金与金融 小计 | D21: =SUM(D15:D20) | E21: =ROUND(SUM(F15:F20)/IF(SUM(D15:D20)=0,1,SUM(D15:D20)),0) | F21: =SUM(F15:F20)
A22: D1 | B22: 分销体系 | C22: 合规二级返佣、T+1 结算（售后无退款后发放）、满 100 元提现、邀请码/推广海报、团队关系 | F22: =IF(OR(D22="",E22=""),"",D22*E22)
A23: D2 | B23: 中介服务 | C23: 服务需求发布与机构匹配、在线下单、服务商工作台、佣金结算 | F23: =IF(OR(D23="",E23=""),"",D23*E23)
A24: D3 | B24: 资质招商 | C24: 招商企业列表（资质核验）、分公司加盟、委托提交与顾问 1 对 1、委托状态流转 | F24: =IF(OR(D24="",E24=""),"",D24*E24)
A25: D4 | B25: 建企买卖 | C25: 转让/收购、信息脱敏、保证金（5000 元/30 天退还）、背调文件、尽调流程 | F25: =IF(OR(D25="",E25=""),"",D25*E25)
A26: D5 | B26: 人员招聘 | C26: 岗位发布与列表、证书核验（四库一平台）、企业付费查看、简历与投递 | F26: =IF(OR(D26="",E26=""),"",D26*E26)
A27: D 增值业务 小计 | D27: =SUM(D22:D26) | E27: =ROUND(SUM(F22:F26)/IF(SUM(D22:D26)=0,1,SUM(D22:D26)),0) | F27: =SUM(F22:F26)
A28: E1 | B28: 首页与频道运营 | C28: 首页频道（招商/转让/人才/服务/综合/资源/供需）、推荐位与运营配置 | F28: =IF(OR(D28="",E28=""),"",D28*E28)
A29: E2 | B29: 内容模块 | C29: 行业资讯、帮助中心、破冰期引导、共创者计划、企业监控 | F29: =IF(OR(D29="",E29=""),"",D29*E29)
A30: E3 | B30: 收藏与浏览历史 | C30: 收藏、浏览历史记录 | F30: =IF(OR(D30="",E30=""),"",D30*E30)
A31: E 内容与生态 小计 | D31: =SUM(D28:D30) | E31: =ROUND(SUM(F28:F30)/IF(SUM(D28:D30)=0,1,SUM(D28:D30)),0) | F31: =SUM(F28:F30)
A32: F1 | B32: 数据总览看板 | C32: 交易额、订单、用户、收入、佣金等核心指标统计 | F32: =IF(OR(D32="",E32=""),"",D32*E32)
A33: F2 | B33: 用户管理 | C33: 用户列表、认证审核、入驻审核（多级流转） | F33: =IF(OR(D33="",E33=""),"",D33*E33)
A34: F3 | B34: 运营管理 | C34: 订单管理、供需管理（审核/上下架）、消息中心（通知/群发） | F34: =IF(OR(D34="",E34=""),"",D34*E34)
A35: F4 | B35: 财务管理 | C35: 钱包总览、充值/对公审批、提现审批、佣金结算、积分管理、发票管理、收入看板 | F35: =IF(OR(D35="",E35=""),"",D35*E35)
A36: F5 | B36: 分销管理 | C36: 分销总览、返佣批次发放（定时）、团队关系树 | F36: =IF(OR(D36="",E36=""),"",D36*E36)
A37: F6 | B37: 中介托管 | C37: 托管资金台账、托管订单（验收/仲裁）、服务商管理 | F37: =IF(OR(D37="",E37=""),"",D37*E37)
A38: F7 | B38: 风控合规 | C38: 合规审计、合规管理、操作日志、企业监控 | F38: =IF(OR(D38="",E38=""),"",D38*E38)
A39: F8 | B39: 系统配置 | C39: 运营周期、定价配置、角色权限 | F39: =IF(OR(D39="",E39=""),"",D39*E39)
A40: F 管理后台 小计 | D40: =SUM(D32:D39) | E40: =ROUND(SUM(F32:F39)/IF(SUM(D32:D39)=0,1,SUM(D32:D39)),0) | F40: =SUM(F32:F39)
...

Sheet 报价汇总
A1: 报价汇总（自动汇总，勿修改）
A2: 分组 | B2: 小计人天 | C2: 小计金额（元） | D2: 说明
A3: A 平台基础 | B3: ='报价表'!D8 | C3: ='报价表'!F8 | D3: 对应需求书模块分组
A4: B 核心交易 | B4: ='报价表'!D14 | C4: ='报价表'!F14 | D4: 对应需求书模块分组
A5: C 资金与金融 | B5: ='报价表'!D21 | C5: ='报价表'!F21 | D5: 对应需求书模块分组
A6: D 增值业务 | B6: ='报价表'!D27 | C6: ='报价表'!F27 | D6: 对应需求书模块分组
A7: E 内容与生态 | B7: ='报价表'!D31 | C7: ='报价表'!F31 | D7: 对应需求书模块分组
A8: F 管理后台 | B8: ='报价表'!D40 | C8: ='报价表'!F40 | D8: 对应需求书模块分组
A9: G 多端与部署 | B9: ='报价表'!D50 | C9: ='报价表'!F50 | D9: 对应需求书模块分组
A10: H 测试与交付 | B10: ='报价表'!D54 | C10: ='报价表'!F54 | D10: 对应需求书模块分组
A11: 总报价（含税） | B11: ='报价表'!D55 | C11: ='报价表'!F55
A13: 说明：本表为「报价表」工作表的自动汇总。乙方填报报价人天与单价后，本表自动更新，无需手工填写。
